<?xml version="1.0" ?>
<robot name="Arm1" xmlns:xacro="http://www.ros.org/wiki/xacro">

<xacro:include filename="$(find arm_description)/urdf/materials.xacro" />
<xacro:include filename="$(find arm_description)/urdf/Arm1.trans" />
<xacro:include filename="$(find arm_description)/urdf/Arm1.gazebo" />
<link name="base_link">
  <inertial>
    <origin xyz="1.280959176633898e-06 0.00443398426662265 -0.04099319631573078" rpy="0 0 0"/>
    <mass value="1.1942675675441157"/>
    <inertia ixx="0.000838" iyy="0.000924" izz="0.001654" ixy="-0.0" iyz="-0.0" ixz="-0.0"/>
  </inertial>
  <visual>
    <origin xyz="0 0 0" rpy="0 0 0"/>
    <geometry>
      <mesh filename="package://arm_description/meshes/base_link.stl" scale="0.001 0.001 0.001"/>
    </geometry>
    <material name="silver"/>
  </visual>
  <collision>
    <origin xyz="0 0 0" rpy="0 0 0"/>
    <geometry>
      <mesh filename="package://arm_description/meshes/base_link.stl" scale="0.001 0.001 0.001"/>
    </geometry>
  </collision>
</link>

<link name="Arm1_de-featured_base_v1_1">
  <inertial>
    <origin xyz="0.011962350835025275 -2.911559882079473e-14 0.006684066539745213" rpy="0 0 0"/>
    <mass value="0.015490383396516524"/>
    <inertia ixx="1e-06" iyy="3e-06" izz="3e-06" ixy="-0.0" iyz="-0.0" ixz="-0.0"/>
  </inertial>
  <visual>
    <origin xyz="0.012 -0.00875 0.025" rpy="0 0 0"/>
    <geometry>
      <mesh filename="package://arm_description/meshes/Arm1_de-featured_base_v1_1.stl" scale="0.001 0.001 0.001"/>
    </geometry>
    <material name="black"/>
  </visual>
  <collision>
    <origin xyz="0.012 -0.00875 0.025" rpy="0 0 0"/>
    <geometry>
      <mesh filename="package://arm_description/meshes/Arm1_de-featured_base_v1_1.stl" scale="0.001 0.001 0.001"/>
    </geometry>
  </collision>
</link>

<link name="Arm1_Fusion2URDF_Arm1_de-featured_doubleJoint_electronicsCover_v1_v1_1">
  <inertial>
    <origin xyz="-2.3661406979947752e-15 0.004302521067873384 0.0424999999999864" rpy="0 0 0"/>
    <mass value="0.038546383418622536"/>
    <inertia ixx="4.9e-05" iyy="5.6e-05" izz="7e-06" ixy="0.0" iyz="0.0" ixz="0.0"/>
  </inertial>
  <visual>
    <origin xyz="-0.0 -0.0355 0.0" rpy="0 0 0"/>
    <geometry>
      <mesh filename="package://arm_description/meshes/Arm1_Fusion2URDF_Arm1_de-featured_doubleJoint_electronicsCover_v1_v1_1.stl" scale="0.001 0.001 0.001"/>
    </geometry>
    <material name="black"/>
  </visual>
  <collision>
    <origin xyz="-0.0 -0.0355 0.0" rpy="0 0 0"/>
    <geometry>
      <mesh filename="package://arm_description/meshes/Arm1_Fusion2URDF_Arm1_de-featured_doubleJoint_electronicsCover_v1_v1_1.stl" scale="0.001 0.001 0.001"/>
    </geometry>
  </collision>
</link>

<link name="Arm1_Fusion2URDF_Arm1_de-featured_armHousing_v1_v1_1">
  <inertial>
    <origin xyz="4.385771140597992e-15 -0.03474077761053653 1.472433286409114e-14" rpy="0 0 0"/>
    <mass value="0.03324824384679508"/>
    <inertia ixx="3.8e-05" iyy="4.8e-05" izz="1.5e-05" ixy="0.0" iyz="0.0" ixz="-0.0"/>
  </inertial>
  <visual>
    <origin xyz="-0.0 -0.035 -0.0425" rpy="0 0 0"/>
    <geometry>
      <mesh filename="package://arm_description/meshes/Arm1_Fusion2URDF_Arm1_de-featured_armHousing_v1_v1_1.stl" scale="0.001 0.001 0.001"/>
    </geometry>
    <material name="gold"/>
  </visual>
  <collision>
    <origin xyz="-0.0 -0.035 -0.0425" rpy="0 0 0"/>
    <geometry>
      <mesh filename="package://arm_description/meshes/Arm1_Fusion2URDF_Arm1_de-featured_armHousing_v1_v1_1.stl" scale="0.001 0.001 0.001"/>
    </geometry>
  </collision>
</link>

<link name="Arm1_Fusion2URDF_Arm1_de-featured_doubleJoint_gearCover_v1_v1_1">
  <inertial>
    <origin xyz="-3.387755705511744e-14 -0.0025800471702999896 -0.04249999999999356" rpy="0 0 0"/>
    <mass value="0.04082339590091089"/>
    <inertia ixx="3.8e-05" iyy="4.5e-05" izz="6e-06" ixy="0.0" iyz="0.0" ixz="0.0"/>
  </inertial>
  <visual>
    <origin xyz="-0.0 0.01 -0.085" rpy="0 0 0"/>
    <geometry>
      <mesh filename="package://arm_description/meshes/Arm1_Fusion2URDF_Arm1_de-featured_doubleJoint_gearCover_v1_v1_1.stl" scale="0.001 0.001 0.001"/>
    </geometry>
    <material name="clear"/>
  </visual>
  <collision>
    <origin xyz="-0.0 0.01 -0.085" rpy="0 0 0"/>
    <geometry>
      <mesh filename="package://arm_description/meshes/Arm1_Fusion2URDF_Arm1_de-featured_doubleJoint_gearCover_v1_v1_1.stl" scale="0.001 0.001 0.001"/>
    </geometry>
  </collision>
</link>

<link name="Arm1_Fusion2URDF_Arm1_de-featured_bearingSupport_v1_v1_1">
  <inertial>
    <origin xyz="-0.020999787123567593 0.011936593580704046 -0.03507452173313677" rpy="0 0 0"/>
    <mass value="0.025170746465891514"/>
    <inertia ixx="2e-05" iyy="2.7e-05" izz="9e-06" ixy="0.0" iyz="-2e-06" ixz="-0.0"/>
  </inertial>
  <visual>
    <origin xyz="-0.021 -0.018 -0.207" rpy="0 0 0"/>
    <geometry>
      <mesh filename="package://arm_description/meshes/Arm1_Fusion2URDF_Arm1_de-featured_bearingSupport_v1_v1_1.stl" scale="0.001 0.001 0.001"/>
    </geometry>
    <material name="gold"/>
  </visual>
  <collision>
    <origin xyz="-0.021 -0.018 -0.207" rpy="0 0 0"/>
    <geometry>
      <mesh filename="package://arm_description/meshes/Arm1_Fusion2URDF_Arm1_de-featured_bearingSupport_v1_v1_1.stl" scale="0.001 0.001 0.001"/>
    </geometry>
  </collision>
</link>

<link name="Arm1_Fusion2URDF_Arm1_de-featured_gearCover_v1_v1_1">
  <inertial>
    <origin xyz="-0.0001264298888167157 -0.0025052801286150703 0.023017088747785658" rpy="0 0 0"/>
    <mass value="0.025259547950496876"/>
    <inertia ixx="1e-05" iyy="1.4e-05" izz="4e-06" ixy="0.0" iyz="-0.0" ixz="0.0"/>
  </inertial>
  <visual>
    <origin xyz="0.0 0.0095 -0.15" rpy="0 0 0"/>
    <geometry>
      <mesh filename="package://arm_description/meshes/Arm1_Fusion2URDF_Arm1_de-featured_gearCover_v1_v1_1.stl" scale="0.001 0.001 0.001"/>
    </geometry>
    <material name="clear"/>
  </visual>
  <collision>
    <origin xyz="0.0 0.0095 -0.15" rpy="0 0 0"/>
    <geometry>
      <mesh filename="package://arm_description/meshes/Arm1_Fusion2URDF_Arm1_de-featured_gearCover_v1_v1_1.stl" scale="0.001 0.001 0.001"/>
    </geometry>
  </collision>
</link>

<link name="Arm1_Fusion2URDF_Arm1_de-featured_electronicsCover_v1_v1_v1_1">
  <inertial>
    <origin xyz="-6.349021698318172e-14 0.004347631607048839 0.016045953544834762" rpy="0 0 0"/>
    <mass value="0.02203612800618232"/>
    <inertia ixx="9e-06" iyy="1.3e-05" izz="4e-06" ixy="0.0" iyz="-0.0" ixz="0.0"/>
  </inertial>
  <visual>
    <origin xyz="0.0 -0.036 -0.15" rpy="0 0 0"/>
    <geometry>
      <mesh filename="package://arm_description/meshes/Arm1_Fusion2URDF_Arm1_de-featured_electronicsCover_v1_v1_v1_1.stl" scale="0.001 0.001 0.001"/>
    </geometry>
    <material name="black"/>
  </visual>
  <collision>
    <origin xyz="0.0 -0.036 -0.15" rpy="0 0 0"/>
    <geometry>
      <mesh filename="package://arm_description/meshes/Arm1_Fusion2URDF_Arm1_de-featured_electronicsCover_v1_v1_v1_1.stl" scale="0.001 0.001 0.001"/>
    </geometry>
  </collision>
</link>

<link name="Arm1_Fusion2URDF_EF_grip_v1_v1__1__1">
  <inertial>
    <origin xyz="-0.001850083275097971 -0.003204213495749954 0.006397387641960739" rpy="0 0 0"/>
    <mass value="0.009673831386691303"/>
    <inertia ixx="0.0" iyy="1e-06" izz="1e-06" ixy="0.0" iyz="0.0" ixz="0.0"/>
  </inertial>
  <visual>
    <origin xyz="0.015 0.011731 -0.2584" rpy="0 0 0"/>
    <geometry>
      <mesh filename="package://arm_description/meshes/Arm1_Fusion2URDF_EF_grip_v1_v1__1__1.stl" scale="0.001 0.001 0.001"/>
    </geometry>
    <material name="black"/>
  </visual>
  <collision>
    <origin xyz="0.015 0.011731 -0.2584" rpy="0 0 0"/>
    <geometry>
      <mesh filename="package://arm_description/meshes/Arm1_Fusion2URDF_EF_grip_v1_v1__1__1.stl" scale="0.001 0.001 0.001"/>
    </geometry>
  </collision>
</link>

<link name="Arm1_Fusion2URDF_EF_grip_v1_v1__2__1">
  <inertial>
    <origin xyz="0.003700177939647664 6.5758094282275525e-09 0.0063973876419607945" rpy="0 0 0"/>
    <mass value="0.009673831386691303"/>
    <inertia ixx="1e-06" iyy="0.0" izz="1e-06" ixy="0.0" iyz="0.0" ixz="-0.0"/>
  </inertial>
  <visual>
    <origin xyz="-0.03 -0.01425 -0.2584" rpy="0 0 0"/>
    <geometry>
      <mesh filename="package://arm_description/meshes/Arm1_Fusion2URDF_EF_grip_v1_v1__2__1.stl" scale="0.001 0.001 0.001"/>
    </geometry>
    <material name="black"/>
  </visual>
  <collision>
    <origin xyz="-0.03 -0.01425 -0.2584" rpy="0 0 0"/>
    <geometry>
      <mesh filename="package://arm_description/meshes/Arm1_Fusion2URDF_EF_grip_v1_v1__2__1.stl" scale="0.001 0.001 0.001"/>
    </geometry>
  </collision>
</link>

<link name="Arm1_Fusion2URDF_EF_grip_v1_v1_1">
  <inertial>
    <origin xyz="-0.0018500946647350483 0.003204206919938682 0.006397387641961405" rpy="0 0 0"/>
    <mass value="0.009673831386691303"/>
    <inertia ixx="0.0" iyy="1e-06" izz="1e-06" ixy="-0.0" iyz="-0.0" ixz="0.0"/>
  </inertial>
  <visual>
    <origin xyz="0.015 -0.040231 -0.2584" rpy="0 0 0"/>
    <geometry>
      <mesh filename="package://arm_description/meshes/Arm1_Fusion2URDF_EF_grip_v1_v1_1.stl" scale="0.001 0.001 0.001"/>
    </geometry>
    <material name="black"/>
  </visual>
  <collision>
    <origin xyz="0.015 -0.040231 -0.2584" rpy="0 0 0"/>
    <geometry>
      <mesh filename="package://arm_description/meshes/Arm1_Fusion2URDF_EF_grip_v1_v1_1.stl" scale="0.001 0.001 0.001"/>
    </geometry>
  </collision>
</link>

<link name="Arm1_Fusion2URDF_Arm1_de-featured_wristHousing_v1_v1_1">
  <inertial>
    <origin xyz="0.02037011900079004 -0.025411886196642863 0.013328921156734314" rpy="0 0 0"/>
    <mass value="0.038841206654025386"/>
    <inertia ixx="2e-05" iyy="1.3e-05" izz="2.8e-05" ixy="0.0" iyz="-0.0" ixz="0.0"/>
  </inertial>
  <visual>
    <origin xyz="0.0205 -0.041 -0.207" rpy="0 0 0"/>
    <geometry>
      <mesh filename="package://arm_description/meshes/Arm1_Fusion2URDF_Arm1_de-featured_wristHousing_v1_v1_1.stl" scale="0.001 0.001 0.001"/>
    </geometry>
    <material name="gold"/>
  </visual>
  <collision>
    <origin xyz="0.0205 -0.041 -0.207" rpy="0 0 0"/>
    <geometry>
      <mesh filename="package://arm_description/meshes/Arm1_Fusion2URDF_Arm1_de-featured_wristHousing_v1_v1_1.stl" scale="0.001 0.001 0.001"/>
    </geometry>
  </collision>
</link>

<link name="Arm1_Fusion2URDF_Arm1_de-featured_wristCover_v1_v1_1">
  <inertial>
    <origin xyz="0.02049999999993821 -0.025323377914748035 0.008807906838274399" rpy="0 0 0"/>
    <mass value="0.03818700044315975"/>
    <inertia ixx="1.5e-05" iyy="8e-06" izz="2.2e-05" ixy="0.0" iyz="0.0" ixz="-0.0"/>
  </inertial>
  <visual>
    <origin xyz="0.0205 -0.041 -0.2315" rpy="0 0 0"/>
    <geometry>
      <mesh filename="package://arm_description/meshes/Arm1_Fusion2URDF_Arm1_de-featured_wristCover_v1_v1_1.stl" scale="0.001 0.001 0.001"/>
    </geometry>
    <material name="gold"/>
  </visual>
  <collision>
    <origin xyz="0.0205 -0.041 -0.2315" rpy="0 0 0"/>
    <geometry>
      <mesh filename="package://arm_description/meshes/Arm1_Fusion2URDF_Arm1_de-featured_wristCover_v1_v1_1.stl" scale="0.001 0.001 0.001"/>
    </geometry>
  </collision>
</link>

<link name="Arm1_de-featured_doubleJoint_bearingSupport_v1_1">
  <inertial>
    <origin xyz="-3.3444607263137293e-15 0.00840699644505781 0.042499999999982316" rpy="0 0 0"/>
    <mass value="0.03393341225951787"/>
    <inertia ixx="5.8e-05" iyy="6.8e-05" izz="1.3e-05" ixy="-0.0" iyz="-0.0" ixz="-0.0"/>
  </inertial>
  <visual>
    <origin xyz="-0.0 -0.0175 0.0" rpy="0 0 0"/>
    <geometry>
      <mesh filename="package://arm_description/meshes/Arm1_de-featured_doubleJoint_bearingSupport_v1_1.stl" scale="0.001 0.001 0.001"/>
    </geometry>
    <material name="gold"/>
  </visual>
  <collision>
    <origin xyz="-0.0 -0.0175 0.0" rpy="0 0 0"/>
    <geometry>
      <mesh filename="package://arm_description/meshes/Arm1_de-featured_doubleJoint_bearingSupport_v1_1.stl" scale="0.001 0.001 0.001"/>
    </geometry>
  </collision>
</link>

<link name="Arm1_Fusion2URDF_Arm1_de-featured_elbow_v1_v1_1">
  <inertial>
    <origin xyz="0.008561725794446499 -0.008750000000000011 0.03250000000004309" rpy="0 0 0"/>
    <mass value="0.023977309097512407"/>
    <inertia ixx="1.1e-05" iyy="1.2e-05" izz="2e-06" ixy="0.0" iyz="-0.0" ixz="-0.0"/>
  </inertial>
  <visual>
    <origin xyz="-0.0 -0.0175 -0.085" rpy="0 0 0"/>
    <geometry>
      <mesh filename="package://arm_description/meshes/Arm1_Fusion2URDF_Arm1_de-featured_elbow_v1_v1_1.stl" scale="0.001 0.001 0.001"/>
    </geometry>
    <material name="black"/>
  </visual>
  <collision>
    <origin xyz="-0.0 -0.0175 -0.085" rpy="0 0 0"/>
    <geometry>
      <mesh filename="package://arm_description/meshes/Arm1_Fusion2URDF_Arm1_de-featured_elbow_v1_v1_1.stl" scale="0.001 0.001 0.001"/>
    </geometry>
  </collision>
</link>

<link name="Arm1_Fusion2URDF_Arm1_de-featured_armHousing_v1__1__v1_1">
  <inertial>
    <origin xyz="-2.991185227266448e-05 -0.00030814304486015854 0.027559175237004824" rpy="0 0 0"/>
    <mass value="0.024910283038556406"/>
    <inertia ixx="1.5e-05" iyy="2.2e-05" izz="1.1e-05" ixy="-0.0" iyz="-0.0" ixz="-0.0"/>
  </inertial>
  <visual>
    <origin xyz="0.0 0.0 -0.15" rpy="0 0 0"/>
    <geometry>
      <mesh filename="package://arm_description/meshes/Arm1_Fusion2URDF_Arm1_de-featured_armHousing_v1__1__v1_1.stl" scale="0.001 0.001 0.001"/>
    </geometry>
    <material name="gold"/>
  </visual>
  <collision>
    <origin xyz="0.0 0.0 -0.15" rpy="0 0 0"/>
    <geometry>
      <mesh filename="package://arm_description/meshes/Arm1_Fusion2URDF_Arm1_de-featured_armHousing_v1__1__v1_1.stl" scale="0.001 0.001 0.001"/>
    </geometry>
  </collision>
</link>

<link name="Arm1_Fusion2URDF_EF_base_v1_v1_1">
  <inertial>
    <origin xyz="-6.13536998983477e-14 -5.533767888366015e-16 0.01056352610936051" rpy="0 0 0"/>
    <mass value="0.052083727437172454"/>
    <inertia ixx="1.4e-05" iyy="1.4e-05" izz="2.5e-05" ixy="0.0" iyz="-0.0" ixz="0.0"/>
  </inertial>
  <visual>
    <origin xyz="0.0 -0.01425 -0.245" rpy="0 0 0"/>
    <geometry>
      <mesh filename="package://arm_description/meshes/Arm1_Fusion2URDF_EF_base_v1_v1_1.stl" scale="0.001 0.001 0.001"/>
    </geometry>
    <material name="black"/>
  </visual>
  <collision>
    <origin xyz="0.0 -0.01425 -0.245" rpy="0 0 0"/>
    <geometry>
      <mesh filename="package://arm_description/meshes/Arm1_Fusion2URDF_EF_base_v1_v1_1.stl" scale="0.001 0.001 0.001"/>
    </geometry>
  </collision>
</link>

<joint name="Rigid1" type="fixed">
  <origin xyz="-0.012 0.00875 -0.025" rpy="0 0 0"/>
  <parent link="base_link"/>
  <child link="Arm1_de-featured_base_v1_1"/>
</joint>

<joint name="Rigid2" type="fixed">
  <origin xyz="0.0 0.018 0.0" rpy="0 0 0"/>
  <parent link="Arm1_de-featured_doubleJoint_bearingSupport_v1_1"/>
  <child link="Arm1_Fusion2URDF_Arm1_de-featured_doubleJoint_electronicsCover_v1_v1_1"/>
</joint>

<joint name="Rigid3" type="fixed">
  <origin xyz="0.0 0.0175 0.0425" rpy="0 0 0"/>
  <parent link="Arm1_de-featured_doubleJoint_bearingSupport_v1_1"/>
  <child link="Arm1_Fusion2URDF_Arm1_de-featured_armHousing_v1_v1_1"/>
</joint>

<joint name="Rigid4" type="fixed">
  <origin xyz="0.0 -0.045 0.0425" rpy="0 0 0"/>
  <parent link="Arm1_Fusion2URDF_Arm1_de-featured_armHousing_v1_v1_1"/>
  <child link="Arm1_Fusion2URDF_Arm1_de-featured_doubleJoint_gearCover_v1_v1_1"/>
</joint>

<joint name="Rigid5" type="fixed">
  <origin xyz="0.021 0.018 0.057" rpy="0 0 0"/>
  <parent link="Arm1_Fusion2URDF_Arm1_de-featured_armHousing_v1__1__v1_1"/>
  <child link="Arm1_Fusion2URDF_Arm1_de-featured_bearingSupport_v1_v1_1"/>
</joint>

<joint name="Rigid6" type="fixed">
  <origin xyz="0.0 -0.0095 0.0" rpy="0 0 0"/>
  <parent link="Arm1_Fusion2URDF_Arm1_de-featured_armHousing_v1__1__v1_1"/>
  <child link="Arm1_Fusion2URDF_Arm1_de-featured_gearCover_v1_v1_1"/>
</joint>

<joint name="Rigid7" type="fixed">
  <origin xyz="-0.021 0.018 -0.057" rpy="0 0 0"/>
  <parent link="Arm1_Fusion2URDF_Arm1_de-featured_bearingSupport_v1_v1_1"/>
  <child link="Arm1_Fusion2URDF_Arm1_de-featured_electronicsCover_v1_v1_v1_1"/>
</joint>

<joint name="Rigid8" type="fixed">
  <origin xyz="-0.015 -0.025981 0.0134" rpy="0 0 0"/>
  <parent link="Arm1_Fusion2URDF_EF_base_v1_v1_1"/>
  <child link="Arm1_Fusion2URDF_EF_grip_v1_v1__1__1"/>
</joint>

<joint name="Rigid9" type="fixed">
  <origin xyz="0.03 0.0 0.0134" rpy="0 0 0"/>
  <parent link="Arm1_Fusion2URDF_EF_base_v1_v1_1"/>
  <child link="Arm1_Fusion2URDF_EF_grip_v1_v1__2__1"/>
</joint>

<joint name="Rigid10" type="fixed">
  <origin xyz="-0.015 0.025981 0.0134" rpy="0 0 0"/>
  <parent link="Arm1_Fusion2URDF_EF_base_v1_v1_1"/>
  <child link="Arm1_Fusion2URDF_EF_grip_v1_v1_1"/>
</joint>

<joint name="Rigid11" type="fixed">
  <origin xyz="-0.0415 0.023 0.0" rpy="0 0 0"/>
  <parent link="Arm1_Fusion2URDF_Arm1_de-featured_bearingSupport_v1_v1_1"/>
  <child link="Arm1_Fusion2URDF_Arm1_de-featured_wristHousing_v1_v1_1"/>
</joint>

<joint name="Rigid12" type="fixed">
  <origin xyz="0.0 0.0 0.0245" rpy="0 0 0"/>
  <parent link="Arm1_Fusion2URDF_Arm1_de-featured_wristHousing_v1_v1_1"/>
  <child link="Arm1_Fusion2URDF_Arm1_de-featured_wristCover_v1_v1_1"/>
</joint>

<joint name="shoulder" type="revolute">
  <origin xyz="0.012 0.00875 0.025" rpy="0 0 0"/>
  <parent link="Arm1_de-featured_base_v1_1"/>
  <child link="Arm1_de-featured_doubleJoint_bearingSupport_v1_1"/>
  <axis xyz="-0.0 1.0 -0.0"/>
  <limit upper="1.22173" lower="-1.22173" effort="100" velocity="100"/>
</joint>

<joint name="elbow_1" type="revolute">
  <origin xyz="0.0 0.0 0.085" rpy="0 0 0"/>
  <parent link="Arm1_de-featured_doubleJoint_bearingSupport_v1_1"/>
  <child link="Arm1_Fusion2URDF_Arm1_de-featured_elbow_v1_v1_1"/>
  <axis xyz="-0.0 1.0 0.0"/>
  <limit upper="1.291544" lower="-1.884956" effort="100" velocity="100"/>
</joint>

<joint name="elbow_2" type="revolute">
  <origin xyz="-0.0 -0.0175 0.065" rpy="0 0 0"/>
  <parent link="Arm1_Fusion2URDF_Arm1_de-featured_elbow_v1_v1_1"/>
  <child link="Arm1_Fusion2URDF_Arm1_de-featured_armHousing_v1__1__v1_1"/>
  <axis xyz="-0.0 1.0 0.0"/>
  <limit upper="1.134464" lower="-1.884956" effort="100" velocity="100"/>
</joint>

<joint name="wrist" type="continuous">
  <origin xyz="0.0205 -0.02675 0.0135" rpy="0 0 0"/>
  <parent link="Arm1_Fusion2URDF_Arm1_de-featured_wristCover_v1_v1_1"/>
  <child link="Arm1_Fusion2URDF_EF_base_v1_v1_1"/>
  <axis xyz="-0.0 -0.0 1.0"/>
</joint>

</robot>
