<?xml version="1.0" ?>
<!-- =================================================================================== -->
<!-- |    This document was autogenerated by xacro from /home/victor/ANT61/ANT61_ws/src/arm_description/urdf/Arm1.xacro | -->
<!-- |    EDITING THIS FILE BY HAND IS NOT RECOMMENDED                                 | -->
<!-- =================================================================================== -->
<robot name="Arm1">
    <material name="silver">
        <color rgba="0.700 0.700 0.700 1.000" />
    </material>
    <material name="gold">
        <color rgba="0.831 0.686 0.216 1.000" />
    </material>
    <material name="black">
        <color rgba="0 0 0 1.000" />
    </material>
    <material name="clear">
        <color rgba="0.7 0.7 0.7 0.6000" />
    </material>
    <transmission name="shoulder_tran">
        <type>transmission_interface/SimpleTransmission</type>
        <joint name="shoulder">
            <hardwareInterface>hardware_interface/PositionJointInterface</hardwareInterface>
        </joint>
        <actuator name="shoulder_actr">
            <hardwareInterface>hardware_interface/PositionJointInterface</hardwareInterface>
            <mechanicalReduction>1</mechanicalReduction>
        </actuator>
    </transmission>
    <transmission name="elbow_1_tran">
        <type>transmission_interface/SimpleTransmission</type>
        <joint name="elbow_1">
            <hardwareInterface>hardware_interface/PositionJointInterface</hardwareInterface>
        </joint>
        <actuator name="elbow_1_actr">
            <hardwareInterface>hardware_interface/PositionJointInterface</hardwareInterface>
            <mechanicalReduction>1</mechanicalReduction>
        </actuator>
    </transmission>
    <transmission name="elbow_2_tran">
        <type>transmission_interface/SimpleTransmission</type>
        <joint name="elbow_2">
            <hardwareInterface>hardware_interface/PositionJointInterface</hardwareInterface>
        </joint>
        <actuator name="elbow_2_actr">
            <hardwareInterface>hardware_interface/PositionJointInterface</hardwareInterface>
            <mechanicalReduction>1</mechanicalReduction>
        </actuator>
    </transmission>
    <transmission name="wrist_tran">
        <type>transmission_interface/SimpleTransmission</type>
        <joint name="wrist">
            <hardwareInterface>hardware_interface/PositionJointInterface</hardwareInterface>
        </joint>
        <actuator name="wrist_actr">
            <hardwareInterface>hardware_interface/PositionJointInterface</hardwareInterface>
            <mechanicalReduction>1</mechanicalReduction>
        </actuator>
    </transmission>
    <gazebo>
        <plugin filename="libgazebo_ros_control.so" name="control" />
        <plugin name="gazebo_ros_control" filename="libgazebo_ros_control.so">
            <robotNamespace>/</robotNamespace>
        </plugin>
    </gazebo>
    <gazebo reference="base_link">
        <material>Gazebo/Black</material>
        <mu1>0.2</mu1>
        <mu2>0.2</mu2>
        <selfCollide>true</selfCollide>
        <gravity>true</gravity>
    </gazebo>
    <gazebo reference="Arm1_de-featured_base_v1_1">
        <material>Gazebo/Silver</material>
        <mu1>0.2</mu1>
        <mu2>0.2</mu2>
        <selfCollide>true</selfCollide>
    </gazebo>
    <gazebo reference="Arm1_Fusion2URDF_Arm1_de-featured_doubleJoint_electronicsCover_v1_v1_1">
        <material>Gazebo/Silver</material>
        <mu1>0.2</mu1>
        <mu2>0.2</mu2>
        <selfCollide>true</selfCollide>
    </gazebo>
    <gazebo reference="Arm1_Fusion2URDF_Arm1_de-featured_armHousing_v1_v1_1">
        <material>Gazebo/Silver</material>
        <mu1>0.2</mu1>
        <mu2>0.2</mu2>
        <selfCollide>true</selfCollide>
    </gazebo>
    <gazebo reference="Arm1_Fusion2URDF_Arm1_de-featured_doubleJoint_gearCover_v1_v1_1">
        <material>Gazebo/Silver</material>
        <mu1>0.2</mu1>
        <mu2>0.2</mu2>
        <selfCollide>true</selfCollide>
    </gazebo>
    <gazebo reference="Arm1_Fusion2URDF_Arm1_de-featured_bearingSupport_v1_v1_1">
        <material>Gazebo/Silver</material>
        <mu1>0.2</mu1>
        <mu2>0.2</mu2>
        <selfCollide>true</selfCollide>
    </gazebo>
    <gazebo reference="Arm1_Fusion2URDF_Arm1_de-featured_gearCover_v1_v1_1">
        <material>Gazebo/Silver</material>
        <mu1>0.2</mu1>
        <mu2>0.2</mu2>
        <selfCollide>true</selfCollide>
    </gazebo>
    <gazebo reference="Arm1_Fusion2URDF_Arm1_de-featured_electronicsCover_v1_v1_v1_1">
        <material>Gazebo/Silver</material>
        <mu1>0.2</mu1>
        <mu2>0.2</mu2>
        <selfCollide>true</selfCollide>
    </gazebo>
    <gazebo reference="Arm1_Fusion2URDF_EF_grip_v1_v1__1__1">
        <material>Gazebo/Silver</material>
        <mu1>0.2</mu1>
        <mu2>0.2</mu2>
        <selfCollide>true</selfCollide>
    </gazebo>
    <gazebo reference="Arm1_Fusion2URDF_EF_grip_v1_v1__2__1">
        <material>Gazebo/Silver</material>
        <mu1>0.2</mu1>
        <mu2>0.2</mu2>
        <selfCollide>true</selfCollide>
    </gazebo>
    <gazebo reference="Arm1_Fusion2URDF_EF_grip_v1_v1_1">
        <material>Gazebo/Silver</material>
        <mu1>0.2</mu1>
        <mu2>0.2</mu2>
        <selfCollide>true</selfCollide>
    </gazebo>
    <gazebo reference="Arm1_Fusion2URDF_Arm1_de-featured_wristHousing_v1_v1_1">
        <material>Gazebo/Silver</material>
        <mu1>0.2</mu1>
        <mu2>0.2</mu2>
        <selfCollide>true</selfCollide>
    </gazebo>
    <gazebo reference="Arm1_Fusion2URDF_Arm1_de-featured_wristCover_v1_v1_1">
        <material>Gazebo/Silver</material>
        <mu1>0.2</mu1>
        <mu2>0.2</mu2>
        <selfCollide>true</selfCollide>
    </gazebo>
    <gazebo reference="Arm1_de-featured_doubleJoint_bearingSupport_v1_1">
        <material>Gazebo/Silver</material>
        <mu1>0.2</mu1>
        <mu2>0.2</mu2>
        <selfCollide>true</selfCollide>
    </gazebo>
    <gazebo reference="Arm1_Fusion2URDF_Arm1_de-featured_elbow_v1_v1_1">
        <material>Gazebo/Silver</material>
        <mu1>0.2</mu1>
        <mu2>0.2</mu2>
        <selfCollide>true</selfCollide>
    </gazebo>
    <gazebo reference="Arm1_Fusion2URDF_Arm1_de-featured_armHousing_v1__1__v1_1">
        <material>Gazebo/Silver</material>
        <mu1>0.2</mu1>
        <mu2>0.2</mu2>
        <selfCollide>true</selfCollide>
    </gazebo>
    <gazebo reference="Arm1_Fusion2URDF_EF_base_v1_v1_1">
        <material>Gazebo/Silver</material>
        <mu1>0.2</mu1>
        <mu2>0.2</mu2>
        <selfCollide>true</selfCollide>
    </gazebo>
    <link name="base_link">
        <inertial>
            <origin rpy="0 0 0" xyz="1.280959176633898e-06 0.00443398426662265 -0.04099319631573078" />
            <mass value="1.1942675675441157" />
            <inertia ixx="0.000838" ixy="-0.0" ixz="-0.0" iyy="0.000924" iyz="-0.0" izz="0.001654" />
        </inertial>
        <visual>
            <origin rpy="0 0 0" xyz="0 0 0" />
            <geometry>
                <mesh filename="package://arm_description/meshes/base_link.stl" scale="0.001 0.001 0.001" />
            </geometry>
            <material name="silver" />
        </visual>
        <collision>
            <origin rpy="0 0 0" xyz="0 0 0" />
            <geometry>
                <mesh filename="package://arm_description/meshes/base_link.stl" scale="0.001 0.001 0.001" />
            </geometry>
        </collision>
    </link>
    <link name="Arm1_de-featured_base_v1_1">
        <inertial>
            <origin rpy="0 0 0" xyz="0.011962350835025275 -2.911559882079473e-14 0.006684066539745213" />
            <mass value="0.015490383396516524" />
            <inertia ixx="1e-06" ixy="-0.0" ixz="-0.0" iyy="3e-06" iyz="-0.0" izz="3e-06" />
        </inertial>
        <visual>
            <origin rpy="0 0 0" xyz="0.012 -0.00875 0.025" />
            <geometry>
                <mesh filename="package://arm_description/meshes/Arm1_de-featured_base_v1_1.stl" scale="0.001 0.001 0.001" />
            </geometry>
            <material name="black" />
        </visual>
        <collision>
            <origin rpy="0 0 0" xyz="0.012 -0.00875 0.025" />
            <geometry>
                <mesh filename="package://arm_description/meshes/Arm1_de-featured_base_v1_1.stl" scale="0.001 0.001 0.001" />
            </geometry>
        </collision>
    </link>
    <link name="Arm1_Fusion2URDF_Arm1_de-featured_doubleJoint_electronicsCover_v1_v1_1">
        <inertial>
            <origin rpy="0 0 0" xyz="-2.3661406979947752e-15 0.004302521067873384 0.0424999999999864" />
            <mass value="0.038546383418622536" />
            <inertia ixx="4.9e-05" ixy="0.0" ixz="0.0" iyy="5.6e-05" iyz="0.0" izz="7e-06" />
        </inertial>
        <visual>
            <origin rpy="0 0 0" xyz="-0.0 -0.0355 0.0" />
            <geometry>
                <mesh filename="package://arm_description/meshes/Arm1_Fusion2URDF_Arm1_de-featured_doubleJoint_electronicsCover_v1_v1_1.stl" scale="0.001 0.001 0.001" />
            </geometry>
            <material name="black" />
        </visual>
        <collision>
            <origin rpy="0 0 0" xyz="-0.0 -0.0355 0.0" />
            <geometry>
                <mesh filename="package://arm_description/meshes/Arm1_Fusion2URDF_Arm1_de-featured_doubleJoint_electronicsCover_v1_v1_1.stl" scale="0.001 0.001 0.001" />
            </geometry>
        </collision>
    </link>
    <link name="Arm1_Fusion2URDF_Arm1_de-featured_armHousing_v1_v1_1">
        <inertial>
            <origin rpy="0 0 0" xyz="4.385771140597992e-15 -0.03474077761053653 1.472433286409114e-14" />
            <mass value="0.03324824384679508" />
            <inertia ixx="3.8e-05" ixy="0.0" ixz="-0.0" iyy="4.8e-05" iyz="0.0" izz="1.5e-05" />
        </inertial>
        <visual>
            <origin rpy="0 0 0" xyz="-0.0 -0.035 -0.0425" />
            <geometry>
                <mesh filename="package://arm_description/meshes/Arm1_Fusion2URDF_Arm1_de-featured_armHousing_v1_v1_1.stl" scale="0.001 0.001 0.001" />
            </geometry>
            <material name="gold" />
        </visual>
        <collision>
            <origin rpy="0 0 0" xyz="-0.0 -0.035 -0.0425" />
            <geometry>
                <mesh filename="package://arm_description/meshes/Arm1_Fusion2URDF_Arm1_de-featured_armHousing_v1_v1_1.stl" scale="0.001 0.001 0.001" />
            </geometry>
        </collision>
    </link>
    <link name="Arm1_Fusion2URDF_Arm1_de-featured_doubleJoint_gearCover_v1_v1_1">
        <inertial>
            <origin rpy="0 0 0" xyz="-3.387755705511744e-14 -0.0025800471702999896 -0.04249999999999356" />
            <mass value="0.04082339590091089" />
            <inertia ixx="3.8e-05" ixy="0.0" ixz="0.0" iyy="4.5e-05" iyz="0.0" izz="6e-06" />
        </inertial>
        <visual>
            <origin rpy="0 0 0" xyz="-0.0 0.01 -0.085" />
            <geometry>
                <mesh filename="package://arm_description/meshes/Arm1_Fusion2URDF_Arm1_de-featured_doubleJoint_gearCover_v1_v1_1.stl" scale="0.001 0.001 0.001" />
            </geometry>
            <material name="clear" />
        </visual>
        <collision>
            <origin rpy="0 0 0" xyz="-0.0 0.01 -0.085" />
            <geometry>
                <mesh filename="package://arm_description/meshes/Arm1_Fusion2URDF_Arm1_de-featured_doubleJoint_gearCover_v1_v1_1.stl" scale="0.001 0.001 0.001" />
            </geometry>
        </collision>
    </link>
    <link name="Arm1_Fusion2URDF_Arm1_de-featured_bearingSupport_v1_v1_1">
        <inertial>
            <origin rpy="0 0 0" xyz="-0.020999787123567593 0.011936593580704046 -0.03507452173313677" />
            <mass value="0.025170746465891514" />
            <inertia ixx="2e-05" ixy="0.0" ixz="-0.0" iyy="2.7e-05" iyz="-2e-06" izz="9e-06" />
        </inertial>
        <visual>
            <origin rpy="0 0 0" xyz="-0.021 -0.018 -0.207" />
            <geometry>
                <mesh filename="package://arm_description/meshes/Arm1_Fusion2URDF_Arm1_de-featured_bearingSupport_v1_v1_1.stl" scale="0.001 0.001 0.001" />
            </geometry>
            <material name="gold" />
        </visual>
        <collision>
            <origin rpy="0 0 0" xyz="-0.021 -0.018 -0.207" />
            <geometry>
                <mesh filename="package://arm_description/meshes/Arm1_Fusion2URDF_Arm1_de-featured_bearingSupport_v1_v1_1.stl" scale="0.001 0.001 0.001" />
            </geometry>
        </collision>
    </link>
    <link name="Arm1_Fusion2URDF_Arm1_de-featured_gearCover_v1_v1_1">
        <inertial>
            <origin rpy="0 0 0" xyz="-0.0001264298888167157 -0.0025052801286150703 0.023017088747785658" />
            <mass value="0.025259547950496876" />
            <inertia ixx="1e-05" ixy="0.0" ixz="0.0" iyy="1.4e-05" iyz="-0.0" izz="4e-06" />
        </inertial>
        <visual>
            <origin rpy="0 0 0" xyz="0.0 0.0095 -0.15" />
            <geometry>
                <mesh filename="package://arm_description/meshes/Arm1_Fusion2URDF_Arm1_de-featured_gearCover_v1_v1_1.stl" scale="0.001 0.001 0.001" />
            </geometry>
            <material name="clear" />
        </visual>
        <collision>
            <origin rpy="0 0 0" xyz="0.0 0.0095 -0.15" />
            <geometry>
                <mesh filename="package://arm_description/meshes/Arm1_Fusion2URDF_Arm1_de-featured_gearCover_v1_v1_1.stl" scale="0.001 0.001 0.001" />
            </geometry>
        </collision>
    </link>
    <link name="Arm1_Fusion2URDF_Arm1_de-featured_electronicsCover_v1_v1_v1_1">
        <inertial>
            <origin rpy="0 0 0" xyz="-6.349021698318172e-14 0.004347631607048839 0.016045953544834762" />
            <mass value="0.02203612800618232" />
            <inertia ixx="9e-06" ixy="0.0" ixz="0.0" iyy="1.3e-05" iyz="-0.0" izz="4e-06" />
        </inertial>
        <visual>
            <origin rpy="0 0 0" xyz="0.0 -0.036 -0.15" />
            <geometry>
                <mesh filename="package://arm_description/meshes/Arm1_Fusion2URDF_Arm1_de-featured_electronicsCover_v1_v1_v1_1.stl" scale="0.001 0.001 0.001" />
            </geometry>
            <material name="black" />
        </visual>
        <collision>
            <origin rpy="0 0 0" xyz="0.0 -0.036 -0.15" />
            <geometry>
                <mesh filename="package://arm_description/meshes/Arm1_Fusion2URDF_Arm1_de-featured_electronicsCover_v1_v1_v1_1.stl" scale="0.001 0.001 0.001" />
            </geometry>
        </collision>
    </link>
    <link name="Arm1_Fusion2URDF_EF_grip_v1_v1__1__1">
        <inertial>
            <origin rpy="0 0 0" xyz="-0.001850083275097971 -0.003204213495749954 0.006397387641960739" />
            <mass value="0.009673831386691303" />
            <inertia ixx="0.0" ixy="0.0" ixz="0.0" iyy="1e-06" iyz="0.0" izz="1e-06" />
        </inertial>
        <visual>
            <origin rpy="0 0 0" xyz="0.015 0.011731 -0.2584" />
            <geometry>
                <mesh filename="package://arm_description/meshes/Arm1_Fusion2URDF_EF_grip_v1_v1__1__1.stl" scale="0.001 0.001 0.001" />
            </geometry>
            <material name="black" />
        </visual>
        <collision>
            <origin rpy="0 0 0" xyz="0.015 0.011731 -0.2584" />
            <geometry>
                <mesh filename="package://arm_description/meshes/Arm1_Fusion2URDF_EF_grip_v1_v1__1__1.stl" scale="0.001 0.001 0.001" />
            </geometry>
        </collision>
    </link>
    <link name="Arm1_Fusion2URDF_EF_grip_v1_v1__2__1">
        <inertial>
            <origin rpy="0 0 0" xyz="0.003700177939647664 6.5758094282275525e-09 0.0063973876419607945" />
            <mass value="0.009673831386691303" />
            <inertia ixx="1e-06" ixy="0.0" ixz="-0.0" iyy="0.0" iyz="0.0" izz="1e-06" />
        </inertial>
        <visual>
            <origin rpy="0 0 0" xyz="-0.03 -0.01425 -0.2584" />
            <geometry>
                <mesh filename="package://arm_description/meshes/Arm1_Fusion2URDF_EF_grip_v1_v1__2__1.stl" scale="0.001 0.001 0.001" />
            </geometry>
            <material name="black" />
        </visual>
        <collision>
            <origin rpy="0 0 0" xyz="-0.03 -0.01425 -0.2584" />
            <geometry>
                <mesh filename="package://arm_description/meshes/Arm1_Fusion2URDF_EF_grip_v1_v1__2__1.stl" scale="0.001 0.001 0.001" />
            </geometry>
        </collision>
    </link>
    <link name="Arm1_Fusion2URDF_EF_grip_v1_v1_1">
        <inertial>
            <origin rpy="0 0 0" xyz="-0.0018500946647350483 0.003204206919938682 0.006397387641961405" />
            <mass value="0.009673831386691303" />
            <inertia ixx="0.0" ixy="-0.0" ixz="0.0" iyy="1e-06" iyz="-0.0" izz="1e-06" />
        </inertial>
        <visual>
            <origin rpy="0 0 0" xyz="0.015 -0.040231 -0.2584" />
            <geometry>
                <mesh filename="package://arm_description/meshes/Arm1_Fusion2URDF_EF_grip_v1_v1_1.stl" scale="0.001 0.001 0.001" />
            </geometry>
            <material name="black" />
        </visual>
        <collision>
            <origin rpy="0 0 0" xyz="0.015 -0.040231 -0.2584" />
            <geometry>
                <mesh filename="package://arm_description/meshes/Arm1_Fusion2URDF_EF_grip_v1_v1_1.stl" scale="0.001 0.001 0.001" />
            </geometry>
        </collision>
    </link>
    <link name="Arm1_Fusion2URDF_Arm1_de-featured_wristHousing_v1_v1_1">
        <inertial>
            <origin rpy="0 0 0" xyz="0.02037011900079004 -0.025411886196642863 0.013328921156734314" />
            <mass value="0.038841206654025386" />
            <inertia ixx="2e-05" ixy="0.0" ixz="0.0" iyy="1.3e-05" iyz="-0.0" izz="2.8e-05" />
        </inertial>
        <visual>
            <origin rpy="0 0 0" xyz="0.0205 -0.041 -0.207" />
            <geometry>
                <mesh filename="package://arm_description/meshes/Arm1_Fusion2URDF_Arm1_de-featured_wristHousing_v1_v1_1.stl" scale="0.001 0.001 0.001" />
            </geometry>
            <material name="gold" />
        </visual>
        <collision>
            <origin rpy="0 0 0" xyz="0.0205 -0.041 -0.207" />
            <geometry>
                <mesh filename="package://arm_description/meshes/Arm1_Fusion2URDF_Arm1_de-featured_wristHousing_v1_v1_1.stl" scale="0.001 0.001 0.001" />
            </geometry>
        </collision>
    </link>
    <link name="Arm1_Fusion2URDF_Arm1_de-featured_wristCover_v1_v1_1">
        <inertial>
            <origin rpy="0 0 0" xyz="0.02049999999993821 -0.025323377914748035 0.008807906838274399" />
            <mass value="0.03818700044315975" />
            <inertia ixx="1.5e-05" ixy="0.0" ixz="-0.0" iyy="8e-06" iyz="0.0" izz="2.2e-05" />
        </inertial>
        <visual>
            <origin rpy="0 0 0" xyz="0.0205 -0.041 -0.2315" />
            <geometry>
                <mesh filename="package://arm_description/meshes/Arm1_Fusion2URDF_Arm1_de-featured_wristCover_v1_v1_1.stl" scale="0.001 0.001 0.001" />
            </geometry>
            <material name="gold" />
        </visual>
        <collision>
            <origin rpy="0 0 0" xyz="0.0205 -0.041 -0.2315" />
            <geometry>
                <mesh filename="package://arm_description/meshes/Arm1_Fusion2URDF_Arm1_de-featured_wristCover_v1_v1_1.stl" scale="0.001 0.001 0.001" />
            </geometry>
        </collision>
    </link>
    <link name="Arm1_de-featured_doubleJoint_bearingSupport_v1_1">
        <inertial>
            <origin rpy="0 0 0" xyz="-3.3444607263137293e-15 0.00840699644505781 0.042499999999982316" />
            <mass value="0.03393341225951787" />
            <inertia ixx="5.8e-05" ixy="-0.0" ixz="-0.0" iyy="6.8e-05" iyz="-0.0" izz="1.3e-05" />
        </inertial>
        <visual>
            <origin rpy="0 0 0" xyz="-0.0 -0.0175 0.0" />
            <geometry>
                <mesh filename="package://arm_description/meshes/Arm1_de-featured_doubleJoint_bearingSupport_v1_1.stl" scale="0.001 0.001 0.001" />
            </geometry>
            <material name="gold" />
        </visual>
        <collision>
            <origin rpy="0 0 0" xyz="-0.0 -0.0175 0.0" />
            <geometry>
                <mesh filename="package://arm_description/meshes/Arm1_de-featured_doubleJoint_bearingSupport_v1_1.stl" scale="0.001 0.001 0.001" />
            </geometry>
        </collision>
    </link>
    <link name="Arm1_Fusion2URDF_Arm1_de-featured_elbow_v1_v1_1">
        <inertial>
            <origin rpy="0 0 0" xyz="0.008561725794446499 -0.008750000000000011 0.03250000000004309" />
            <mass value="0.023977309097512407" />
            <inertia ixx="1.1e-05" ixy="0.0" ixz="-0.0" iyy="1.2e-05" iyz="-0.0" izz="2e-06" />
        </inertial>
        <visual>
            <origin rpy="0 0 0" xyz="-0.0 -0.0175 -0.085" />
            <geometry>
                <mesh filename="package://arm_description/meshes/Arm1_Fusion2URDF_Arm1_de-featured_elbow_v1_v1_1.stl" scale="0.001 0.001 0.001" />
            </geometry>
            <material name="black" />
        </visual>
        <collision>
            <origin rpy="0 0 0" xyz="-0.0 -0.0175 -0.085" />
            <geometry>
                <mesh filename="package://arm_description/meshes/Arm1_Fusion2URDF_Arm1_de-featured_elbow_v1_v1_1.stl" scale="0.001 0.001 0.001" />
            </geometry>
        </collision>
    </link>
    <link name="Arm1_Fusion2URDF_Arm1_de-featured_armHousing_v1__1__v1_1">
        <inertial>
            <origin rpy="0 0 0" xyz="-2.991185227266448e-05 -0.00030814304486015854 0.027559175237004824" />
            <mass value="0.024910283038556406" />
            <inertia ixx="1.5e-05" ixy="-0.0" ixz="-0.0" iyy="2.2e-05" iyz="-0.0" izz="1.1e-05" />
        </inertial>
        <visual>
            <origin rpy="0 0 0" xyz="0.0 0.0 -0.15" />
            <geometry>
                <mesh filename="package://arm_description/meshes/Arm1_Fusion2URDF_Arm1_de-featured_armHousing_v1__1__v1_1.stl" scale="0.001 0.001 0.001" />
            </geometry>
            <material name="gold" />
        </visual>
        <collision>
            <origin rpy="0 0 0" xyz="0.0 0.0 -0.15" />
            <geometry>
                <mesh filename="package://arm_description/meshes/Arm1_Fusion2URDF_Arm1_de-featured_armHousing_v1__1__v1_1.stl" scale="0.001 0.001 0.001" />
            </geometry>
        </collision>
    </link>
    <link name="Arm1_Fusion2URDF_EF_base_v1_v1_1">
        <inertial>
            <origin rpy="0 0 0" xyz="-6.13536998983477e-14 -5.533767888366015e-16 0.01056352610936051" />
            <mass value="0.052083727437172454" />
            <inertia ixx="1.4e-05" ixy="0.0" ixz="0.0" iyy="1.4e-05" iyz="-0.0" izz="2.5e-05" />
        </inertial>
        <visual>
            <origin rpy="0 0 0" xyz="0.0 -0.01425 -0.245" />
            <geometry>
                <mesh filename="package://arm_description/meshes/Arm1_Fusion2URDF_EF_base_v1_v1_1.stl" scale="0.001 0.001 0.001" />
            </geometry>
            <material name="black" />
        </visual>
        <collision>
            <origin rpy="0 0 0" xyz="0.0 -0.01425 -0.245" />
            <geometry>
                <mesh filename="package://arm_description/meshes/Arm1_Fusion2URDF_EF_base_v1_v1_1.stl" scale="0.001 0.001 0.001" />
            </geometry>
        </collision>
    </link>
    <joint name="Rigid1" type="fixed">
        <origin rpy="0 0 0" xyz="-0.012 0.00875 -0.025" />
        <parent link="base_link" />
        <child link="Arm1_de-featured_base_v1_1" />
    </joint>
    <joint name="Rigid2" type="fixed">
        <origin rpy="0 0 0" xyz="0.0 0.018 0.0" />
        <parent link="Arm1_de-featured_doubleJoint_bearingSupport_v1_1" />
        <child link="Arm1_Fusion2URDF_Arm1_de-featured_doubleJoint_electronicsCover_v1_v1_1" />
    </joint>
    <joint name="Rigid3" type="fixed">
        <origin rpy="0 0 0" xyz="0.0 0.0175 0.0425" />
        <parent link="Arm1_de-featured_doubleJoint_bearingSupport_v1_1" />
        <child link="Arm1_Fusion2URDF_Arm1_de-featured_armHousing_v1_v1_1" />
    </joint>
    <joint name="Rigid4" type="fixed">
        <origin rpy="0 0 0" xyz="0.0 -0.045 0.0425" />
        <parent link="Arm1_Fusion2URDF_Arm1_de-featured_armHousing_v1_v1_1" />
        <child link="Arm1_Fusion2URDF_Arm1_de-featured_doubleJoint_gearCover_v1_v1_1" />
    </joint>
    <joint name="Rigid5" type="fixed">
        <origin rpy="0 0 0" xyz="0.021 0.018 0.057" />
        <parent link="Arm1_Fusion2URDF_Arm1_de-featured_armHousing_v1__1__v1_1" />
        <child link="Arm1_Fusion2URDF_Arm1_de-featured_bearingSupport_v1_v1_1" />
    </joint>
    <joint name="Rigid6" type="fixed">
        <origin rpy="0 0 0" xyz="0.0 -0.0095 0.0" />
        <parent link="Arm1_Fusion2URDF_Arm1_de-featured_armHousing_v1__1__v1_1" />
        <child link="Arm1_Fusion2URDF_Arm1_de-featured_gearCover_v1_v1_1" />
    </joint>
    <joint name="Rigid7" type="fixed">
        <origin rpy="0 0 0" xyz="-0.021 0.018 -0.057" />
        <parent link="Arm1_Fusion2URDF_Arm1_de-featured_bearingSupport_v1_v1_1" />
        <child link="Arm1_Fusion2URDF_Arm1_de-featured_electronicsCover_v1_v1_v1_1" />
    </joint>
    <joint name="Rigid8" type="fixed">
        <origin rpy="0 0 0" xyz="-0.015 -0.025981 0.0134" />
        <parent link="Arm1_Fusion2URDF_EF_base_v1_v1_1" />
        <child link="Arm1_Fusion2URDF_EF_grip_v1_v1__1__1" />
    </joint>
    <joint name="Rigid9" type="fixed">
        <origin rpy="0 0 0" xyz="0.03 0.0 0.0134" />
        <parent link="Arm1_Fusion2URDF_EF_base_v1_v1_1" />
        <child link="Arm1_Fusion2URDF_EF_grip_v1_v1__2__1" />
    </joint>
    <joint name="Rigid10" type="fixed">
        <origin rpy="0 0 0" xyz="-0.015 0.025981 0.0134" />
        <parent link="Arm1_Fusion2URDF_EF_base_v1_v1_1" />
        <child link="Arm1_Fusion2URDF_EF_grip_v1_v1_1" />
    </joint>
    <joint name="Rigid11" type="fixed">
        <origin rpy="0 0 0" xyz="-0.0415 0.023 0.0" />
        <parent link="Arm1_Fusion2URDF_Arm1_de-featured_bearingSupport_v1_v1_1" />
        <child link="Arm1_Fusion2URDF_Arm1_de-featured_wristHousing_v1_v1_1" />
    </joint>
    <joint name="Rigid12" type="fixed">
        <origin rpy="0 0 0" xyz="0.0 0.0 0.0245" />
        <parent link="Arm1_Fusion2URDF_Arm1_de-featured_wristHousing_v1_v1_1" />
        <child link="Arm1_Fusion2URDF_Arm1_de-featured_wristCover_v1_v1_1" />
    </joint>
    <joint name="shoulder" type="revolute">
        <origin rpy="0 0 0" xyz="0.012 0.00875 0.025" />
        <parent link="Arm1_de-featured_base_v1_1" />
        <child link="Arm1_de-featured_doubleJoint_bearingSupport_v1_1" />
        <axis xyz="-0.0 1.0 -0.0" />
        <limit effort="100" lower="-1.22173" upper="1.22173" velocity="100" />
    </joint>
    <joint name="elbow_1" type="revolute">
        <origin rpy="0 0 0" xyz="0.0 0.0 0.085" />
        <parent link="Arm1_de-featured_doubleJoint_bearingSupport_v1_1" />
        <child link="Arm1_Fusion2URDF_Arm1_de-featured_elbow_v1_v1_1" />
        <axis xyz="-0.0 1.0 0.0" />
        <limit effort="100" lower="-1.884956" upper="1.291544" velocity="100" />
    </joint>
    <joint name="elbow_2" type="revolute">
        <origin rpy="0 0 0" xyz="-0.0 -0.0175 0.065" />
        <parent link="Arm1_Fusion2URDF_Arm1_de-featured_elbow_v1_v1_1" />
        <child link="Arm1_Fusion2URDF_Arm1_de-featured_armHousing_v1__1__v1_1" />
        <axis xyz="-0.0 1.0 0.0" />
        <limit effort="100" lower="-1.884956" upper="1.134464" velocity="100" />
    </joint>
    <joint name="wrist" type="continuous">
        <origin rpy="0 0 0" xyz="0.0205 -0.02675 0.0135" />
        <parent link="Arm1_Fusion2URDF_Arm1_de-featured_wristCover_v1_v1_1" />
        <child link="Arm1_Fusion2URDF_EF_base_v1_v1_1" />
        <axis xyz="-0.0 -0.0 1.0" />
    </joint>
</robot>

